Workbook

Sheet README
A1: Hope Cement Works — Amine Optimization & WHR Integration Model
A2: v2 — supersedes the earlier oxy-fuel-vs-amine comparison after confirming Breedon's own stated technology choice
A5: WHAT CHANGED FROM v1
A6: Breedon publicly stated (March 2025 community meeting) that amine scrubbing is "closest to realisation" for Hope, with disclosed internal estimates of ~£400M for capture and ~£300M for pipeline transport. Source: hopevalleyclimateaction.org.uk. Separately, an EA permit decision document confirms Hope's two kilns were installed in the early 1970s with a multistage cyclone preheater but NO CALCINER — a materially harder oxy-fuel retrofit case than the modern-precalciner literature (CEMCAP etc.) assumes, since there's no separate calciner vessel to convert; you'd be converting the main kiln burner flame itself.
A8: v1 compared amine vs. oxy-fuel as ALTERNATIVE capture technologies. That framing fights Breedon's own £400M decision. v2 instead treats the amine plant as a given and asks: what's the smallest capital add-on that meaningfully cuts its operating cost? Both Baseline and Optimized below include the SAME £400M amine plant — the comparison is the incremental value of the add-on package.
A10: THE ADD-ON PACKAGE (Optimized case)
A11: 1. WHR thermal integration: route kiln waste heat DIRECTLY to the amine reboiler's steam demand (not through an ORC turbine to electricity — direct thermal use avoids the ~80% conversion loss an ORC would impose, and reboiler duty is exactly the kind of low-grade heat load kiln waste heat is good for).
A12: 2. De-SOx pretreatment: Hope's local shale has unusually high pyritic sulphur (confirmed in the EA permit — SOx emission limits well above the normal BAT-AEL range). SO2 reacts irreversibly with amine solvent, forming heat-stable salts that degrade it — a real, sourced OpEx risk for the £400M asset. A pretreatment step protects the solvent.
A13: 3. BESS: buffers the compression load feeding the Peak Cluster pipeline connection, same grid-queue-avoidance logic as v1.
A15: CONFIDENCE LEVELS
A16: HIGH: amine capex (£333/tpa, matches Breedon's disclosed £400M almost exactly), reboiler duty, compression energy, UK ETS price.
A17: MEDIUM: specific heat consumption for a 1970s preheater-no-calciner kiln (3.3-4.2 GJ/t range, cement engineering literature), waste heat recoverable fraction, heat transfer efficiency.
... A21: Incremental capex (~£61M) against incremental annual opex savings (~£18.5M/yr) gives a ~3.3 year simple payback — a normal, fundable industrial capital project, not a bet-the-technology pivot. It works WITH Breedon's own £400M decision rather than against it.

Sheet Assumptions
A1: Assumptions
A2: Edit only the blue values. Kiln thermal rating is now a FORMULA (clinker tonnage x specific heat / operating hours), not a fixed guess.
A4: Parameter | B4: Value | C4: Unit | D4: Source / Confidence
A6: SITE & TARGET
A7: Annual clinker production | B7: 1250000 | C7: t/yr | D7: MEDIUM — estimated from 1.5Mt/yr cement capacity x ~0.85 clinker:cement ratio (UK typical)
A8: Specific heat consumption | B8: 3.8 | C8: GJ/t clinker | D8: MEDIUM — 1970s preheater-only kiln, NO calciner (EA permit decision doc). Range 3.3-4.2 GJ/t for this kiln type; modern precalciner kilns run 2.9-3.3
A9: Kiln operating hours | B9: 8000 | C9: hrs/yr | D9: Typical continuous kiln operation (~91% capacity factor)
A10: Kiln thermal rating (DERIVED) | B10: =(B7*B8*1000000000)/(B9*3600)/1000000 | C10: MWth | D10: Formula: clinker t/yr x GJ/t clinker / operating seconds, converted to MW. Not a published nameplate figure — recompute if you get a real one from Breedon.
A11: Target annual CO2 to pipeline | B11: 1200000 | C11: t/yr | D11: HIGH — Hope Valley Climate Action: Hope is "by far the largest emitter of greenhouse gases in the Hope Valley", ~1.2Mt CO2/yr
A12: Baseline flue gas CO2 concentration | B12: 0.2 | C12: % | D12: Sourcing-table proxy for cement kilns (18-22%)
A13: Reference CO2% used to scale amine energy penalty | B13: 0.2 | C13: % | D13: Modelling reference point
A15: PRICES
A16: Grid electricity tariff | B16: 105 | C16: £/MWh | D16: MEDIUM — DESNZ/Ofgem-informed range for large industrial users, £85-140
A17: Thermal (steam) energy cost, purchased | B17: 35 | C17: £/MWh-th | D17: MEDIUM — placeholder gas-fired steam cost
A18: UK ETS price (2026 civil penalty rate) | B18: 49.41 | C18: £/t CO2 | D18: HIGH — UK ETS Authority 2026 published rate
A20: FINANCE
A21: Discount rate | B21: 0.08 | C21: % | D21: Placeholder WACC
A22: Plant/asset life | B22: 20 | C22: years | D22: Typical industrial capital asset life
A24: SHARED — CO2 COMPRESSION
A25: Compression energy to pipeline spec | B25: 105 | C25: kWh/t CO2 | D25: HIGH — standard CCS benchmark, 90-120 kWh/t
A27: AMINE PLANT (shared by both cases — Breedon's £400M plan)
A28: Amine plant capex | B28: 333 | C28: £/tpa capacity | D28: HIGH — matches Breedon's disclosed ~£400M for Hope almost exactly (£333/tpa x 1.2Mt = £399.6M)
A29: Amine reboiler (thermal) duty, at reference CO2% | B29: 900 | C29: kWh-th/t CO2 | D29: HIGH — typical MEA ~3.0-3.5 GJ/t CO2
A30: Amine electrical auxiliary load | B30: 40 | C30: kWh/t CO2 | D30: HIGH — typical amine plant benchmark
A32: BASELINE-ONLY — UNMITIGATED SOx RISK
A33: Baseline-only opex — SOx degradation risk (D), coupled point estimate | B33: 3.28 | C33: £/t CO2 | D33: LOW/placeholder — midpoint of £12-15/t range; SO2 forms heat-stable salts with amine solvent, spiking makeup/replacement cost. Hope's local pyritic shale gives elevated SOx (confirmed in EA permit)
A35: OPTIMIZED-ONLY — ADD-ON PACKAGE
A36: Amine non-energy opex, PROTECTED (with De-SOx pretreatment) | B36: 8 | C36: £/t CO2 | D36: Same clean-solvent rate as v1's original placeholder — applies once pretreatment removes the SOx threat
A37: De-SOx incremental capex, CENTRAL CASE (standard pretreatment assumed inside £400M baseline) | B37: 0 | C37: £/tpa CO2 capacity | D37: LOW/placeholder — no public benchmark found; needs vendor quote. Likely a polishing/cooling step, not full FGD, since kiln already has some SOx control
A38: De-SOx protection opex (P), coupled point estimate — NaOH + Na2SO4 waste + 15% uplift | B38: 1.19 | C38: £/t CO2 | D38: LOW/placeholder — reagent + maintenance
A39: Recoverable waste heat | B39: 0.35 | C39: % of kiln thermal input | D39: MEDIUM — cement industry reports 30-40% of kiln/clinker-cooler heat wasted
A40: Heat transfer efficiency (recovered heat -> usable reboiler steam) | B40: 0.85 | C40: % | D40: MEDIUM/placeholder — heat exchanger losses and temperature/quality matching; not all recovered heat is usable as reboiler-grade steam
A41: WHR thermal-integration capex | B41: 99600 | C41: £/MWth recoverable | D41: MEDIUM-HIGH — Biermann, Anantharaman & Harvey, Table B1/B2 cement case studies (9 variants), correctly de-annualized using the PAPER'S OWN stated assumptions (7.5% interest rate, 25yr lifetime, 8000 op-hrs/yr — confirmed in their published assumptions table; op-hrs matches this model's own assumption independently). Adjusted 2016->2026 EUR terms using Eurostat EU HICP cumulative inflation (+33.0% to 2025, Eurostat, plus ~2026 partial year). EUR->GBP at flat 0.80 (not inflation-adjusted separately - a further refinement opportunity). Their case studies are 13-14 MWth vs Hope's ~58 MWth recoverable - untested scale-economy extrapolation remains the main residual uncertainty. Range across 9 variants, 2026 terms: £73,800-£141,700/MWth.
A42: BESS capex | B42: 280 | C42: £/kWh installed | D42: MEDIUM — UK commercial/industrial BESS range £200-450/kWh
A43: BESS power rating | B43: 10 | C43: MW | D43: User input — sized to buffer compression peak load
A44: BESS duration | B44: 4 | C44: hours | D44: User input
A45: Avoided/delayed grid-reinforcement value | B45: 3000000 | C45: £ | D45: LOW/placeholder — needs DNO quote
A47: DE-SOX METHODOLOGY MEMO (Aug 2026 v4) — see Monte Carlo notebook Section 2b for full derivation
A48: Source: Hope Cement Works EA Decision Document (2017, gov.uk, permit EPR/BP3731VJ)
A49: Point estimates above use inlet SOx = 700 mg/Nm3 (confirmed actual 2017 operating midpoint, 600-800mg/Nm3 band, reported as 2,030 t SO2/yr)
...

Sheet Baseline
A1: Baseline — Amine As-Planned (Breedon's £400M plan)
A2: No WHR integration, no De-SOx pretreatment — unmitigated pyritic-sulphur solvent degradation risk.
A4: Metric | B4: Value | C4: Unit | D4: Note
A6: Annual CO2 volume | B6: =Assumptions!$B$11 | C6: t/yr
A7: Amine reboiler duty, adjusted for actual flue gas CO2% | B7: =Assumptions!$B$29*(Assumptions!$B$13/Assumptions!$B$12) | C7: kWh-th/t CO2
A8: Thermal energy cost (fully purchased — no WHR offset) | B8: =B7*Assumptions!$B$17/1000 | C8: £/t CO2
A9: Electrical load (amine aux + compression) | B9: =Assumptions!$B$30+Assumptions!$B$25 | C9: kWh/t CO2
A10: Electrical cost | B10: =B9*Assumptions!$B$16/1000 | C10: £/t CO2
A11: Non-energy opex — SOx degradation risk (D), coupled to inlet SOx via Chapel/TERC threshold | B11: =Assumptions!$B$33 | C11: £/t CO2
A12: Total opex | B12: =B8+B10+B11 | C12: £/t CO2
A13: Annual opex | B13: =B12*B6 | C13: £/yr
A15: CAPEX & LEVELIZATION
A16: Amine plant capex (Breedon's £400M) | B16: =Assumptions!$B$28*B6 | C16: £
A17: Capital recovery factor (CRF) | B17: =(Assumptions!$B$21*(1+Assumptions!$B$21)^Assumptions!$B$22)/((1+Assumptions!$B$21)^Assumptions!$B$22-1)
A18: Annualized capex | B18: =B16*B17 | C18: £/yr
A19: Levelized capex | B19: =B18/B6 | C19: £/t CO2
A20: ALL-IN LEVELIZED COST | B20: =B12+B19 | C20: £/t CO2

Sheet Optimized
A1: Optimized — Amine + WHR Thermal Integration + De-SOx + BESS
A2: SAME £400M amine plant as Baseline, PLUS a smaller add-on package. Kiln waste heat feeds the reboiler directly (not via ORC electricity).
A4: Metric | B4: Value | C4: Unit | D4: Note
A6: Annual CO2 volume | B6: =Assumptions!$B$11 | C6: t/yr
A7: WASTE HEAT -> REBOILER (DIRECT THERMAL, NOT ORC ELECTRICITY)
A8: Recoverable waste heat | B8: =Assumptions!$B$10*Assumptions!$B$39 | C8: MWth
A9: Usable heat after heat-exchanger transfer losses | B9: =B8*Assumptions!$B$40 | C9: MWth
A10: Annual recovered thermal energy | B10: =B9*Assumptions!$B$9 | C10: MWh-th/yr
A11: Reboiler thermal demand (adjusted for CO2%) | B11: =Assumptions!$B$29*(Assumptions!$B$13/Assumptions!$B$12)*B6/1000 | C11: MWh-th/yr
A12: Purchased thermal energy (shortfall after WHR) | B12: =MAX(0,B11-B10) | C12: MWh-th/yr
A13: Share of reboiler duty covered by recovered heat | B13: =MIN(1,B10/B11) | C13: %
A15: OPEX
A16: Purchased thermal cost | B16: =B12*Assumptions!$B$17 | C16: £/yr
A17: Electrical cost (aux + compression, unchanged) | B17: =(Assumptions!$B$30+Assumptions!$B$25)*B6/1000*Assumptions!$B$16 | C17: £/yr
A18: Non-energy opex (protected amine + De-SOx protection opex P, coupled/physics-based) | B18: =(Assumptions!$B$36+Assumptions!$B$38)*B6 | C18: £/yr
A19: Total opex | B19: =B16+B17+B18 | C19: £/yr
A20: Total opex | B20: =B19/B6 | C20: £/t CO2
A22: CAPEX & LEVELIZATION
A23: Amine plant capex (SAME base plant as Baseline) | B23: =Assumptions!$B$28*B6 | C23: £
A24: De-SOx incremental capex (CENTRAL CASE = £0; standard pretreatment assumed inside baseline — see Assumptions memo) | B24: =Assumptions!$B$37*B6 | C24: £
A25: WHR thermal-integration capex | B25: =Assumptions!$B$41*B8 | C25: £
A26: BESS capex | B26: =Assumptions!$B$43*Assumptions!$B$44*1000*Assumptions!$B$42 | C26: £
A27: Add-on capex, gross (DeSOx + WHR + BESS) | B27: =B24+B25+B26 | C27: £
A28: Avoided/delayed grid-reinforcement value | B28: =Assumptions!$B$45 | C28: £
A29: Add-on capex, net | B29: =B27-B28 | C29: £
A30: Total capex (base plant + net add-on) | B30: =B23+B29 | C30: £
A31: Capital recovery factor (CRF) | B31: =Baseline!B17
A32: Annualized capex | B32: =B30*B31 | C32: £/yr
A33: Levelized capex | B33: =B32/B6 | C33: £/t CO2
A34: ALL-IN LEVELIZED COST | B34: =B20+B33 | C34: £/t CO2

Sheet Comparison
A1: Comparison — Amine As-Planned vs Amine + WHR/De-SOx/BESS Add-On
A2: Both cases include the SAME £400M amine plant. This is the value of the add-on package only.
A4: Metric | B4: Value | C4: Unit | D4: Note
A6: ALL-IN LEVELIZED COST
A7: Baseline (amine as-planned) — all-in £/t | B7: =Baseline!$B$20 | C7: £/t CO2
A8: Optimized (+ WHR/De-SOx/BESS) — all-in £/t | B8: =Optimized!$B$34 | C8: £/t CO2
A9: Savings per tonne | B9: =B7-B8 | C9: £/t CO2
A10: Savings, % | B10: =B9/B7 | C10: %
A11: UK ETS price (reference only) | B11: =Assumptions!$B$18 | C11: £/t CO2
A13: THE ACTUAL PITCH NUMBERS: INCREMENTAL CAPEX vs INCREMENTAL SAVINGS
A14: Add-on capex (DeSOx + WHR + BESS, net of grid offset) | B14: =Optimized!$B$29 | C14: £
A15: Baseline annual opex | B15: =Baseline!$B$13 | C15: £/yr
A16: Optimized annual opex | B16: =Optimized!$B$19 | C16: £/yr
A17: Annual opex savings | B17: =B15-B16 | C17: £/yr
A18: Simple payback on the add-on package | B18: =IF(B17<=0,"N/A",B14/B17) | C18: years
A20: WHAT THE ADD-ON IS ACTUALLY BUYING
A21: Share of reboiler thermal duty covered by recovered waste heat | B21: =Optimized!$B$13 | C21: % | D21: This is a technology-agnostic saving — works whether Breedon sticks with amine or ever revisits capture tech

Sheet Sensitivity
A1: Sensitivity
A2: Payback period (years) vs the two least-certain inputs: specific heat consumption (drives kiln MWth, hence WHR supply) and De-SOx scenario (central = £0 vs polisher downside).
A4: TABLE 1 — Simple payback (years) vs specific heat consumption and De-SOx capex
A5: GJ/t \ De-SOx scenario £/tpa | B5: 0 | C5: 15 | D5: 25 | E5: 25
A6: 3.3 | B6: =IF((Baseline!$B$13-((MAX(0,(Assumptions!$B$29*(Assumptions!$B$13/Assumptions!$B$12)*Optimized!$B$6/1000)-((((Assumptions!$B$7*$A6*1000000000)/(Assumptions!$B$9*3600)/1000000*Assumptions!$B$39)*Assumptions!$B$40)*Assumptions!$B$9))*Assumptions!$B$17)+((Assumptions!$B$30+Assumptions!$B$25)*Optimized!$B$6/1000*Assumptions!$B$16)+((Assumptions!$B$36+Assumptions!$B$38)*Optimized!$B$6)))<=0,"N/A",(((B$5*Optimized!$B$6)+(Assumptions!$B$41*((Assumptions!$B$7*$A6*1000000000)/(Assumptions!$B$9*3600)/1000000*Assumptions!$B$39))+Optimized!$B$26)-Assumptions!$B$45)/(Baseline!$B$13-((MAX(0,(Assumptions!$B$29*(Assumptions!$B$13/Assumptions!$B$12)*Optimized!$B$6/1000)-((((Assumptions!$B$7*$A6*1000000000)/(Assumptions!$B$9*3600)/1000000*Assumptions!$B$39)*Assumptions!$B$40)*Assumptions!$B$9))*Assumptions!$B$17)+((Assumptions!$B$30+Assumptions!$B$25)*Optimized!$B$6/1000*Assumptions!$B$16)+((Assumptions!$B$36+Assumptions!$B$38)*Optimized!$B$6)))) | C6: =IF((Baseline!$B$13-((MAX(0,(Assumptions!$B$29*(Assumptions!$B$13/Assumptions!$B$12)*Optimized!$B$6/1000)-((((Assumptions!$B$7*$A6*1000000000)/(Assumptions!$B$9*3600)/1000000*Assumptions!$B$39)*Assumptions!$B$40)*Assumptions!$B$9))*Assumptions!$B$17)+((Assumptions!$B$30+Assumptions!$B$25)*Optimized!$B$6/1000*Assumptions!$B$16)+((Assumptions!$B$36+Assumptions!$B$38)*Optimized!$B$6)))<=0,"N/A",(((C$5*Optimized!$B$6)+(Assumptions!$B$41*((Assumptions!$B$7*$A6*1000000000)/(Assumptions!$B$9*3600)/1000000*Assumptions!$B$39))+Optimized!$B$26)-Assumptions!$B$45)/(Baseline!$B$13-((MAX(0,(Assumptions!$B$29*(Assumptions!$B$13/Assumptions!$B$12)*Optimized!$B$6/1000)-((((Assumptions!$B$7*$A6*1000000000)/(Assumptions!$B$9*3600)/1000000*Assumptions!$B$39)*Assumptions!$B$40)*Assumptions!$B$9))*Assumptions!$B$17)+((Assumptions!$B$30+Assumptions!$B$25)*Optimized!$B$6/1000*Assumptions!$B$16)+((Assumptions!$B$36+Assumptions!$B$38)*Optimized!$B$6)))) | D6: =IF((Baseline!$B$13-((MAX(0,(Assumptions!$B$29*(Assumptions!$B$13/Assumptions!$B$12)*Optimized!$B$6/1000)-((((Assumptions!$B$7*$A6*1000000000)/(Assumptions!$B$9*3600)/1000000*Assumptions!$B$39)*Assumptions!$B$40)*Assumptions!$B$9))*Assumptions!$B$17)+((Assumptions!$B$30+Assumptions!$B$25)*Optimized!$B$6/1000*Assumptions!$B$16)+((Assumptions!$B$36+Assumptions!$B$38)*Optimized!$B$6)))<=0,"N/A",(((D$5*Optimized!$B$6)+(Assumptions!$B$41*((Assumptions!$B$7*$A6*1000000000)/(Assumptions!$B$9*3600)/1000000*Assumptions!$B$39))+Optimized!$B$26)-Assumptions!$B$45)/(Baseline!$B$13-((MAX(0,(Assumptions!$B$29*(Assumptions!$B$13/Assumptions!$B$12)*Optimized!$B$6/1000)-((((Assumptions!$B$7*$A6*1000000000)/(Assumptions!$B$9*3600)/1000000*Assumptions!$B$39)*Assumptions!$B$40)*Assumptions!$B$9))*Assumptions!$B$17)+((Assumptions!$B$30+Assumptions!$B$25)*Optimized!$B$6/1000*Assumptions!$B$16)+((Assumptions!$B$36+Assumptions!$B$38)*Optimized!$B$6)))) | E6: =IF((Baseline!$B$13-((MAX(0,(Assumptions!$B$29*(Assumptions!$B$13/Assumptions!$B$12)*Optimized!$B$6/1000)-((((Assumptions!$B$7*$A6*1000000000)/(Assumptions!$B$9*3600)/1000000*Assumptions!$B$39)*Assumptions!$B$40)*Assumptions!$B$9))*Assumptions!$B$17)+((Assumptions!$B$30+Assumptions!$B$25)*Optimized!$B$6/1000*Assumptions!$B$16)+((Assumptions!$B$36+Assumptions!$B$38)*Optimized!$B$6)))<=0,"N/A",(((E$5*Optimized!$B$6)+(Assumptions!$B$41*((Assumptions!$B$7*$A6*1000000000)/(Assumptions!$B$9*3600)/1000000*Assumptions!$B$39))+Optimized!$B$26)-Assumptions!$B$45)/(Baseline!$B$13-((MAX(0,(Assumptions!$B$29*(Assumptions!$B$13/Assumptions!$B$12)*Optimized!$B$6/1000)-((((Assumptions!$B$7*$A6*1000000000)/(Assumptions!$B$9*3600)/1000000*Assumptions!$B$39)*Assumptions!$B$40)*Assumptions!$B$9))*Assumptions!$B$17)+((Assumptions!$B$30+Assumptions!$B$25)*Optimized!$B$6/1000*Assumptions!$B$16)+((Assumptions!$B$36+Assumptions!$B$38)*Optimized!$B$6))))
A7: 3.5 | B7: =IF((Baseline!$B$13-((MAX(0,(Assumptions!$B$29*(Assumptions!$B$13/Assumptions!$B$12)*Optimized!$B$6/1000)-((((Assumptions!$B$7*$A7*1000000000)/(Assumptions!$B$9*3600)/1000000*Assumptions!$B$39)*Assumptions!$B$40)*Assumptions!$B$9))*Assumptions!$B$17)+((Assumptions!$B$30+Assumptions!$B$25)*Optimized!$B$6/1000*Assumptions!$B$16)+((Assumptions!$B$36+Assumptions!$B$38)*Optimized!$B$6)))<=0,"N/A",(((B$5*Optimized!$B$6)+(Assumptions!$B$41*((Assumptions!$B$7*$A7*1000000000)/(Assumptions!$B$9*3600)/1000000*Assumptions!$B$39))+Optimized!$B$26)-Assumptions!$B$45)/(Baseline!$B$13-((MAX(0,(Assumptions!$B$29*(Assumptions!$B$13/Assumptions!$B$12)*Optimized!$B$6/1000)-((((Assumptions!$B$7*$A7*1000000000)/(Assumptions!$B$9*3600)/1000000*Assumptions!$B$39)*Assumptions!$B$40)*Assumptions!$B$9))*Assumptions!$B$17)+((Assumptions!$B$30+Assumptions!$B$25)*Optimized!$B$6/1000*Assumptions!$B$16)+((Assumptions!$B$36+Assumptions!$B$38)*Optimized!$B$6)))) | C7: =IF((Baseline!$B$13-((MAX(0,(Assumptions!$B$29*(Assumptions!$B$13/Assumptions!$B$12)*Optimized!$B$6/1000)-((((Assumptions!$B$7*$A7*1000000000)/(Assumptions!$B$9*3600)/1000000*Assumptions!$B$39)*Assumptions!$B$40)*Assumptions!$B$9))*Assumptions!$B$17)+((Assumptions!$B$30+Assumptions!$B$25)*Optimized!$B$6/1000*Assumptions!$B$16)+((Assumptions!$B$36+Assumptions!$B$38)*Optimized!$B$6)))<=0,"N/A",(((C$5*Optimized!$B$6)+(Assumptions!$B$41*((Assumptions!$B$7*$A7*1000000000)/(Assumptions!$B$9*3600)/1000000*Assumptions!$B$39))+Optimized!$B$26)-Assumptions!$B$45)/(Baseline!$B$13-((MAX(0,(Assumptions!$B$29*(Assumptions!$B$13/Assumptions!$B$12)*Optimized!$B$6/1000)-((((Assumptions!$B$7*$A7*1000000000)/(Assumptions!$B$9*3600)/1000000*Assumptions!$B$39)*Assumptions!$B$40)*Assumptions!$B$9))*Assumptions!$B$17)+((Assumptions!$B$30+Assumptions!$B$25)*Optimized!$B$6/1000*Assumptions!$B$16)+((Assumptions!$B$36+Assumptions!$B$38)*Optimized!$B$6)))) | D7: =IF((Baseline!$B$13-((MAX(0,(Assumptions!$B$29*(Assumptions!$B$13/Assumptions!$B$12)*Optimized!$B$6/1000)-((((Assumptions!$B$7*$A7*1000000000)/(Assumptions!$B$9*3600)/1000000*Assumptions!$B$39)*Assumptions!$B$40)*Assumptions!$B$9))*Assumptions!$B$17)+((Assumptions!$B$30+Assumptions!$B$25)*Optimized!$B$6/1000*Assumptions!$B$16)+((Assumptions!$B$36+Assumptions!$B$38)*Optimized!$B$6)))<=0,"N/A",(((D$5*Optimized!$B$6)+(Assumptions!$B$41*((Assumptions!$B$7*$A7*1000000000)/(Assumptions!$B$9*3600)/1000000*Assumptions!$B$39))+Optimized!$B$26)-Assumptions!$B$45)/(Baseline!$B$13-((MAX(0,(Assumptions!$B$29*(Assumptions!$B$13/Assumptions!$B$12)*Optimized!$B$6/1000)-((((Assumptions!$B$7*$A7*1000000000)/(Assumptions!$B$9*3600)/1000000*Assumptions!$B$39)*Assumptions!$B$40)*Assumptions!$B$9))*Assumptions!$B$17)+((Assumptions!$B$30+Assumptions!$B$25)*Optimized!$B$6/1000*Assumptions!$B$16)+((Assumptions!$B$36+Assumptions!$B$38)*Optimized!$B$6)))) | E7: =IF((Baseline!$B$13-((MAX(0,(Assumptions!$B$29*(Assumptions!$B$13/Assumptions!$B$12)*Optimized!$B$6/1000)-((((Assumptions!$B$7*$A7*1000000000)/(Assumptions!$B$9*3600)/1000000*Assumptions!$B$39)*Assumptions!$B$40)*Assumptions!$B$9))*Assumptions!$B$17)+((Assumptions!$B$30+Assumptions!$B$25)*Optimized!$B$6/1000*Assumptions!$B$16)+((Assumptions!$B$36+Assumptions!$B$38)*Optimized!$B$6)))<=0,"N/A",(((E$5*Optimized!$B$6)+(Assumptions!$B$41*((Assumptions!$B$7*$A7*1000000000)/(Assumptions!$B$9*3600)/1000000*Assumptions!$B$39))+Optimized!$B$26)-Assumptions!$B$45)/(Baseline!$B$13-((MAX(0,(Assumptions!$B$29*(Assumptions!$B$13/Assumptions!$B$12)*Optimized!$B$6/1000)-((((Assumptions!$B$7*$A7*1000000000)/(Assumptions!$B$9*3600)/1000000*Assumptions!$B$39)*Assumptions!$B$40)*Assumptions!$B$9))*Assumptions!$B$17)+((Assumptions!$B$30+Assumptions!$B$25)*Optimized!$B$6/1000*Assumptions!$B$16)+((Assumptions!$B$36+Assumptions!$B$38)*Optimized!$B$6))))
A8: 3.7 | B8: =IF((Baseline!$B$13-((MAX(0,(Assumptions!$B$29*(Assumptions!$B$13/Assumptions!$B$12)*Optimized!$B$6/1000)-((((Assumptions!$B$7*$A8*1000000000)/(Assumptions!$B$9*3600)/1000000*Assumptions!$B$39)*Assumptions!$B$40)*Assumptions!$B$9))*Assumptions!$B$17)+((Assumptions!$B$30+Assumptions!$B$25)*Optimized!$B$6/1000*Assumptions!$B$16)+((Assumptions!$B$36+Assumptions!$B$38)*Optimized!$B$6)))<=0,"N/A",(((B$5*Optimized!$B$6)+(Assumptions!$B$41*((Assumptions!$B$7*$A8*1000000000)/(Assumptions!$B$9*3600)/1000000*Assumptions!$B$39))+Optimized!$B$26)-Assumptions!$B$45)/(Baseline!$B$13-((MAX(0,(Assumptions!$B$29*(Assumptions!$B$13/Assumptions!$B$12)*Optimized!$B$6/1000)-((((Assumptions!$B$7*$A8*1000000000)/(Assumptions!$B$9*3600)/1000000*Assumptions!$B$39)*Assumptions!$B$40)*Assumptions!$B$9))*Assumptions!$B$17)+((Assumptions!$B$30+Assumptions!$B$25)*Optimized!$B$6/1000*Assumptions!$B$16)+((Assumptions!$B$36+Assumptions!$B$38)*Optimized!$B$6)))) | C8: =IF((Baseline!$B$13-((MAX(0,(Assumptions!$B$29*(Assumptions!$B$13/Assumptions!$B$12)*Optimized!$B$6/1000)-((((Assumptions!$B$7*$A8*1000000000)/(Assumptions!$B$9*3600)/1000000*Assumptions!$B$39)*Assumptions!$B$40)*Assumptions!$B$9))*Assumptions!$B$17)+((Assumptions!$B$30+Assumptions!$B$25)*Optimized!$B$6/1000*Assumptions!$B$16)+((Assumptions!$B$36+Assumptions!$B$38)*Optimized!$B$6)))<=0,"N/A",(((C$5*Optimized!$B$6)+(Assumptions!$B$41*((Assumptions!$B$7*$A8*1000000000)/(Assumptions!$B$9*3600)/1000000*Assumptions!$B$39))+Optimized!$B$26)-Assumptions!$B$45)/(Baseline!$B$13-((MAX(0,(Assumptions!$B$29*(Assumptions!$B$13/Assumptions!$B$12)*Optimized!$B$6/1000)-((((Assumptions!$B$7*$A8*1000000000)/(Assumptions!$B$9*3600)/1000000*Assumptions!$B$39)*Assumptions!$B$40)*Assumptions!$B$9))*Assumptions!$B$17)+((Assumptions!$B$30+Assumptions!$B$25)*Optimized!$B$6/1000*Assumptions!$B$16)+((Assumptions!$B$36+Assumptions!$B$38)*Optimized!$B$6)))) | D8: =IF((Baseline!$B$13-((MAX(0,(Assumptions!$B$29*(Assumptions!$B$13/Assumptions!$B$12)*Optimized!$B$6/1000)-((((Assumptions!$B$7*$A8*1000000000)/(Assumptions!$B$9*3600)/1000000*Assumptions!$B$39)*Assumptions!$B$40)*Assumptions!$B$9))*Assumptions!$B$17)+((Assumptions!$B$30+Assumptions!$B$25)*Optimized!$B$6/1000*Assumptions!$B$16)+((Assumptions!$B$36+Assumptions!$B$38)*Optimized!$B$6)))<=0,"N/A",(((D$5*Optimized!$B$6)+(Assumptions!$B$41*((Assumptions!$B$7*$A8*1000000000)/(Assumptions!$B$9*3600)/1000000*Assumptions!$B$39))+Optimized!$B$26)-Assumptions!$B$45)/(Baseline!$B$13-((MAX(0,(Assumptions!$B$29*(Assumptions!$B$13/Assumptions!$B$12)*Optimized!$B$6/1000)-((((Assumptions!$B$7*$A8*1000000000)/(Assumptions!$B$9*3600)/1000000*Assumptions!$B$39)*Assumptions!$B$40)*Assumptions!$B$9))*Assumptions!$B$17)+((Assumptions!$B$30+Assumptions!$B$25)*Optimized!$B$6/1000*Assumptions!$B$16)+((Assumptions!$B$36+Assumptions!$B$38)*Optimized!$B$6)))) | E8: =IF((Baseline!$B$13-((MAX(0,(Assumptions!$B$29*(Assumptions!$B$13/Assumptions!$B$12)*Optimized!$B$6/1000)-((((Assumptions!$B$7*$A8*1000000000)/(Assumptions!$B$9*3600)/1000000*Assumptions!$B$39)*Assumptions!$B$40)*Assumptions!$B$9))*Assumptions!$B$17)+((Assumptions!$B$30+Assumptions!$B$25)*Optimized!$B$6/1000*Assumptions!$B$16)+((Assumptions!$B$36+Assumptions!$B$38)*Optimized!$B$6)))<=0,"N/A",(((E$5*Optimized!$B$6)+(Assumptions!$B$41*((Assumptions!$B$7*$A8*1000000000)/(Assumptions!$B$9*3600)/1000000*Assumptions!$B$39))+Optimized!$B$26)-Assumptions!$B$45)/(Baseline!$B$13-((MAX(0,(Assumptions!$B$29*(Assumptions!$B$13/Assumptions!$B$12)*Optimized!$B$6/1000)-((((Assumptions!$B$7*$A8*1000000000)/(Assumptions!$B$9*3600)/1000000*Assumptions!$B$39)*Assumptions!$B$40)*Assumptions!$B$9))*Assumptions!$B$17)+((Assumptions!$B$30+Assumptions!$B$25)*Optimized!$B$6/1000*Assumptions!$B$16)+((Assumptions!$B$36+Assumptions!$B$38)*Optimized!$B$6))))
A9: 3.8 | B9: =IF((Baseline!$B$13-((MAX(0,(Assumptions!$B$29*(Assumptions!$B$13/Assumptions!$B$12)*Optimized!$B$6/1000)-((((Assumptions!$B$7*$A9*1000000000)/(Assumptions!$B$9*3600)/1000000*Assumptions!$B$39)*Assumptions!$B$40)*Assumptions!$B$9))*Assumptions!$B$17)+((Assumptions!$B$30+Assumptions!$B$25)*Optimized!$B$6/1000*Assumptions!$B$16)+((Assumptions!$B$36+Assumptions!$B$38)*Optimized!$B$6)))<=0,"N/A",(((B$5*Optimized!$B$6)+(Assumptions!$B$41*((Assumptions!$B$7*$A9*1000000000)/(Assumptions!$B$9*3600)/1000000*Assumptions!$B$39))+Optimized!$B$26)-Assumptions!$B$45)/(Baseline!$B$13-((MAX(0,(Assumptions!$B$29*(Assumptions!$B$13/Assumptions!$B$12)*Optimized!$B$6/1000)-((((Assumptions!$B$7*$A9*1000000000)/(Assumptions!$B$9*3600)/1000000*Assumptions!$B$39)*Assumptions!$B$40)*Assumptions!$B$9))*Assumptions!$B$17)+((Assumptions!$B$30+Assumptions!$B$25)*Optimized!$B$6/1000*Assumptions!$B$16)+((Assumptions!$B$36+Assumptions!$B$38)*Optimized!$B$6)))) | C9: =IF((Baseline!$B$13-((MAX(0,(Assumptions!$B$29*(Assumptions!$B$13/Assumptions!$B$12)*Optimized!$B$6/1000)-((((Assumptions!$B$7*$A9*1000000000)/(Assumptions!$B$9*3600)/1000000*Assumptions!$B$39)*Assumptions!$B$40)*Assumptions!$B$9))*Assumptions!$B$17)+((Assumptions!$B$30+Assumptions!$B$25)*Optimized!$B$6/1000*Assumptions!$B$16)+((Assumptions!$B$36+Assumptions!$B$38)*Optimized!$B$6)))<=0,"N/A",(((C$5*Optimized!$B$6)+(Assumptions!$B$41*((Assumptions!$B$7*$A9*1000000000)/(Assumptions!$B$9*3600)/1000000*Assumptions!$B$39))+Optimized!$B$26)-Assumptions!$B$45)/(Baseline!$B$13-((MAX(0,(Assumptions!$B$29*(Assumptions!$B$13/Assumptions!$B$12)*Optimized!$B$6/1000)-((((Assumptions!$B$7*$A9*1000000000)/(Assumptions!$B$9*3600)/1000000*Assumptions!$B$39)*Assumptions!$B$40)*Assumptions!$B$9))*Assumptions!$B$17)+((Assumptions!$B$30+Assumptions!$B$25)*Optimized!$B$6/1000*Assumptions!$B$16)+((Assumptions!$B$36+Assumptions!$B$38)*Optimized!$B$6)))) | D9: =IF((Baseline!$B$13-((MAX(0,(Assumptions!$B$29*(Assumptions!$B$13/Assumptions!$B$12)*Optimized!$B$6/1000)-((((Assumptions!$B$7*$A9*1000000000)/(Assumptions!$B$9*3600)/1000000*Assumptions!$B$39)*Assumptions!$B$40)*Assumptions!$B$9))*Assumptions!$B$17)+((Assumptions!$B$30+Assumptions!$B$25)*Optimized!$B$6/1000*Assumptions!$B$16)+((Assumptions!$B$36+Assumptions!$B$38)*Optimized!$B$6)))<=0,"N/A",(((D$5*Optimized!$B$6)+(Assumptions!$B$41*((Assumptions!$B$7*$A9*1000000000)/(Assumptions!$B$9*3600)/1000000*Assumptions!$B$39))+Optimized!$B$26)-Assumptions!$B$45)/(Baseline!$B$13-((MAX(0,(Assumptions!$B$29*(Assumptions!$B$13/Assumptions!$B$12)*Optimized!$B$6/1000)-((((Assumptions!$B$7*$A9*1000000000)/(Assumptions!$B$9*3600)/1000000*Assumptions!$B$39)*Assumptions!$B$40)*Assumptions!$B$9))*Assumptions!$B$17)+((Assumptions!$B$30+Assumptions!$B$25)*Optimized!$B$6/1000*Assumptions!$B$16)+((Assumptions!$B$36+Assumptions!$B$38)*Optimized!$B$6)))) | E9: =IF((Baseline!$B$13-((MAX(0,(Assumptions!$B$29*(Assumptions!$B$13/Assumptions!$B$12)*Optimized!$B$6/1000)-((((Assumptions!$B$7*$A9*1000000000)/(Assumptions!$B$9*3600)/1000000*Assumptions!$B$39)*Assumptions!$B$40)*Assumptions!$B$9))*Assumptions!$B$17)+((Assumptions!$B$30+Assumptions!$B$25)*Optimized!$B$6/1000*Assumptions!$B$16)+((Assumptions!$B$36+Assumptions!$B$38)*Optimized!$B$6)))<=0,"N/A",(((E$5*Optimized!$B$6)+(Assumptions!$B$41*((Assumptions!$B$7*$A9*1000000000)/(Assumptions!$B$9*3600)/1000000*Assumptions!$B$39))+Optimized!$B$26)-Assumptions!$B$45)/(Baseline!$B$13-((MAX(0,(Assumptions!$B$29*(Assumptions!$B$13/Assumptions!$B$12)*Optimized!$B$6/1000)-((((Assumptions!$B$7*$A9*1000000000)/(Assumptions!$B$9*3600)/1000000*Assumptions!$B$39)*Assumptions!$B$40)*Assumptions!$B$9))*Assumptions!$B$17)+((Assumptions!$B$30+Assumptions!$B$25)*Optimized!$B$6/1000*Assumptions!$B$16)+((Assumptions!$B$36+Assumptions!$B$38)*Optimized!$B$6))))
A10: 3.9 | B10: =IF((Baseline!$B$13-((MAX(0,(Assumptions!$B$29*(Assumptions!$B$13/Assumptions!$B$12)*Optimized!$B$6/1000)-((((Assumptions!$B$7*$A10*1000000000)/(Assumptions!$B$9*3600)/1000000*Assumptions!$B$39)*Assumptions!$B$40)*Assumptions!$B$9))*Assumptions!$B$17)+((Assumptions!$B$30+Assumptions!$B$25)*Optimized!$B$6/1000*Assumptions!$B$16)+((Assumptions!$B$36+Assumptions!$B$38)*Optimized!$B$6)))<=0,"N/A",(((B$5*Optimized!$B$6)+(Assumptions!$B$41*((Assumptions!$B$7*$A10*1000000000)/(Assumptions!$B$9*3600)/1000000*Assumptions!$B$39))+Optimized!$B$26)-Assumptions!$B$45)/(Baseline!$B$13-((MAX(0,(Assumptions!$B$29*(Assumptions!$B$13/Assumptions!$B$12)*Optimized!$B$6/1000)-((((Assumptions!$B$7*$A10*1000000000)/(Assumptions!$B$9*3600)/1000000*Assumptions!$B$39)*Assumptions!$B$40)*Assumptions!$B$9))*Assumptions!$B$17)+((Assumptions!$B$30+Assumptions!$B$25)*Optimized!$B$6/1000*Assumptions!$B$16)+((Assumptions!$B$36+Assumptions!$B$38)*Optimized!$B$6)))) | C10: =IF((Baseline!$B$13-((MAX(0,(Assumptions!$B$29*(Assumptions!$B$13/Assumptions!$B$12)*Optimized!$B$6/1000)-((((Assumptions!$B$7*$A10*1000000000)/(Assumptions!$B$9*3600)/1000000*Assumptions!$B$39)*Assumptions!$B$40)*Assumptions!$B$9))*Assumptions!$B$17)+((Assumptions!$B$30+Assumptions!$B$25)*Optimized!$B$6/1000*Assumptions!$B$16)+((Assumptions!$B$36+Assumptions!$B$38)*Optimized!$B$6)))<=0,"N/A",(((C$5*Optimized!$B$6)+(Assumptions!$B$41*((Assumptions!$B$7*$A10*1000000000)/(Assumptions!$B$9*3600)/1000000*Assumptions!$B$39))+Optimized!$B$26)-Assumptions!$B$45)/(Baseline!$B$13-((MAX(0,(Assumptions!$B$29*(Assumptions!$B$13/Assumptions!$B$12)*Optimized!$B$6/1000)-((((Assumptions!$B$7*$A10*1000000000)/(Assumptions!$B$9*3600)/1000000*Assumptions!$B$39)*Assumptions!$B$40)*Assumptions!$B$9))*Assumptions!$B$17)+((Assumptions!$B$30+Assumptions!$B$25)*Optimized!$B$6/1000*Assumptions!$B$16)+((Assumptions!$B$36+Assumptions!$B$38)*Optimized!$B$6)))) | D10: =IF((Baseline!$B$13-((MAX(0,(Assumptions!$B$29*(Assumptions!$B$13/Assumptions!$B$12)*Optimized!$B$6/1000)-((((Assumptions!$B$7*$A10*1000000000)/(Assumptions!$B$9*3600)/1000000*Assumptions!$B$39)*Assumptions!$B$40)*Assumptions!$B$9))*Assumptions!$B$17)+((Assumptions!$B$30+Assumptions!$B$25)*Optimized!$B$6/1000*Assumptions!$B$16)+((Assumptions!$B$36+Assumptions!$B$38)*Optimized!$B$6)))<=0,"N/A",(((D$5*Optimized!$B$6)+(Assumptions!$B$41*((Assumptions!$B$7*$A10*1000000000)/(Assumptions!$B$9*3600)/1000000*Assumptions!$B$39))+Optimized!$B$26)-Assumptions!$B$45)/(Baseline!$B$13-((MAX(0,(Assumptions!$B$29*(Assumptions!$B$13/Assumptions!$B$12)*Optimized!$B$6/1000)-((((Assumptions!$B$7*$A10*1000000000)/(Assumptions!$B$9*3600)/1000000*Assumptions!$B$39)*Assumptions!$B$40)*Assumptions!$B$9))*Assumptions!$B$17)+((Assumptions!$B$30+Assumptions!$B$25)*Optimized!$B$6/1000*Assumptions!$B$16)+((Assumptions!$B$36+Assumptions!$B$38)*Optimized!$B$6)))) | E10: =IF((Baseline!$B$13-((MAX(0,(Assumptions!$B$29*(Assumptions!$B$13/Assumptions!$B$12)*Optimized!$B$6/1000)-((((Assumptions!$B$7*$A10*1000000000)/(Assumptions!$B$9*3600)/1000000*Assumptions!$B$39)*Assumptions!$B$40)*Assumptions!$B$9))*Assumptions!$B$17)+((Assumptions!$B$30+Assumptions!$B$25)*Optimized!$B$6/1000*Assumptions!$B$16)+((Assumptions!$B$36+Assumptions!$B$38)*Optimized!$B$6)))<=0,"N/A",(((E$5*Optimized!$B$6)+(Assumptions!$B$41*((Assumptions!$B$7*$A10*1000000000)/(Assumptions!$B$9*3600)/1000000*Assumptions!$B$39))+Optimized!$B$26)-Assumptions!$B$45)/(Baseline!$B$13-((MAX(0,(Assumptions!$B$29*(Assumptions!$B$13/Assumptions!$B$12)*Optimized!$B$6/1000)-((((Assumptions!$B$7*$A10*1000000000)/(Assumptions!$B$9*3600)/1000000*Assumptions!$B$39)*Assumptions!$B$40)*Assumptions!$B$9))*Assumptions!$B$17)+((Assumptions!$B$30+Assumptions!$B$25)*Optimized!$B$6/1000*Assumptions!$B$16)+((Assumptions!$B$36+Assumptions!$B$38)*Optimized!$B$6))))
A11: 4 | B11: =IF((Baseline!$B$13-((MAX(0,(Assumptions!$B$29*(Assumptions!$B$13/Assumptions!$B$12)*Optimized!$B$6/1000)-((((Assumptions!$B$7*$A11*1000000000)/(Assumptions!$B$9*3600)/1000000*Assumptions!$B$39)*Assumptions!$B$40)*Assumptions!$B$9))*Assumptions!$B$17)+((Assumptions!$B$30+Assumptions!$B$25)*Optimized!$B$6/1000*Assumptions!$B$16)+((Assumptions!$B$36+Assumptions!$B$38)*Optimized!$B$6)))<=0,"N/A",(((B$5*Optimized!$B$6)+(Assumptions!$B$41*((Assumptions!$B$7*$A11*1000000000)/(Assumptions!$B$9*3600)/1000000*Assumptions!$B$39))+Optimized!$B$26)-Assumptions!$B$45)/(Baseline!$B$13-((MAX(0,(Assumptions!$B$29*(Assumptions!$B$13/Assumptions!$B$12)*Optimized!$B$6/1000)-((((Assumptions!$B$7*$A11*1000000000)/(Assumptions!$B$9*3600)/1000000*Assumptions!$B$39)*Assumptions!$B$40)*Assumptions!$B$9))*Assumptions!$B$17)+((Assumptions!$B$30+Assumptions!$B$25)*Optimized!$B$6/1000*Assumptions!$B$16)+((Assumptions!$B$36+Assumptions!$B$38)*Optimized!$B$6)))) | C11: =IF((Baseline!$B$13-((MAX(0,(Assumptions!$B$29*(Assumptions!$B$13/Assumptions!$B$12)*Optimized!$B$6/1000)-((((Assumptions!$B$7*$A11*1000000000)/(Assumptions!$B$9*3600)/1000000*Assumptions!$B$39)*Assumptions!$B$40)*Assumptions!$B$9))*Assumptions!$B$17)+((Assumptions!$B$30+Assumptions!$B$25)*Optimized!$B$6/1000*Assumptions!$B$16)+((Assumptions!$B$36+Assumptions!$B$38)*Optimized!$B$6)))<=0,"N/A",(((C$5*Optimized!$B$6)+(Assumptions!$B$41*((Assumptions!$B$7*$A11*1000000000)/(Assumptions!$B$9*3600)/1000000*Assumptions!$B$39))+Optimized!$B$26)-Assumptions!$B$45)/(Baseline!$B$13-((MAX(0,(Assumptions!$B$29*(Assumptions!$B$13/Assumptions!$B$12)*Optimized!$B$6/1000)-((((Assumptions!$B$7*$A11*1000000000)/(Assumptions!$B$9*3600)/1000000*Assumptions!$B$39)*Assumptions!$B$40)*Assumptions!$B$9))*Assumptions!$B$17)+((Assumptions!$B$30+Assumptions!$B$25)*Optimized!$B$6/1000*Assumptions!$B$16)+((Assumptions!$B$36+Assumptions!$B$38)*Optimized!$B$6)))) | D11: =IF((Baseline!$B$13-((MAX(0,(Assumptions!$B$29*(Assumptions!$B$13/Assumptions!$B$12)*Optimized!$B$6/1000)-((((Assumptions!$B$7*$A11*1000000000)/(Assumptions!$B$9*3600)/1000000*Assumptions!$B$39)*Assumptions!$B$40)*Assumptions!$B$9))*Assumptions!$B$17)+((Assumptions!$B$30+Assumptions!$B$25)*Optimized!$B$6/1000*Assumptions!$B$16)+((Assumptions!$B$36+Assumptions!$B$38)*Optimized!$B$6)))<=0,"N/A",(((D$5*Optimized!$B$6)+(Assumptions!$B$41*((Assumptions!$B$7*$A11*1000000000)/(Assumptions!$B$9*3600)/1000000*Assumptions!$B$39))+Optimized!$B$26)-Assumptions!$B$45)/(Baseline!$B$13-((MAX(0,(Assumptions!$B$29*(Assumptions!$B$13/Assumptions!$B$12)*Optimized!$B$6/1000)-((((Assumptions!$B$7*$A11*1000000000)/(Assumptions!$B$9*3600)/1000000*Assumptions!$B$39)*Assumptions!$B$40)*Assumptions!$B$9))*Assumptions!$B$17)+((Assumptions!$B$30+Assumptions!$B$25)*Optimized!$B$6/1000*Assumptions!$B$16)+((Assumptions!$B$36+Assumptions!$B$38)*Optimized!$B$6)))) | E11: =IF((Baseline!$B$13-((MAX(0,(Assumptions!$B$29*(Assumptions!$B$13/Assumptions!$B$12)*Optimized!$B$6/1000)-((((Assumptions!$B$7*$A11*1000000000)/(Assumptions!$B$9*3600)/1000000*Assumptions!$B$39)*Assumptions!$B$40)*Assumptions!$B$9))*Assumptions!$B$17)+((Assumptions!$B$30+Assumptions!$B$25)*Optimized!$B$6/1000*Assumptions!$B$16)+((Assumptions!$B$36+Assumptions!$B$38)*Optimized!$B$6)))<=0,"N/A",(((E$5*Optimized!$B$6)+(Assumptions!$B$41*((Assumptions!$B$7*$A11*1000000000)/(Assumptions!$B$9*3600)/1000000*Assumptions!$B$39))+Optimized!$B$26)-Assumptions!$B$45)/(Baseline!$B$13-((MAX(0,(Assumptions!$B$29*(Assumptions!$B$13/Assumptions!$B$12)*Optimized!$B$6/1000)-((((Assumptions!$B$7*$A11*1000000000)/(Assumptions!$B$9*3600)/1000000*Assumptions!$B$39)*Assumptions!$B$40)*Assumptions!$B$9))*Assumptions!$B$17)+((Assumptions!$B$30+Assumptions!$B$25)*Optimized!$B$6/1000*Assumptions!$B$16)+((Assumptions!$B$36+Assumptions!$B$38)*Optimized!$B$6))))
A12: 4.2 | B12: =IF((Baseline!$B$13-((MAX(0,(Assumptions!$B$29*(Assumptions!$B$13/Assumptions!$B$12)*Optimized!$B$6/1000)-((((Assumptions!$B$7*$A12*1000000000)/(Assumptions!$B$9*3600)/1000000*Assumptions!$B$39)*Assumptions!$B$40)*Assumptions!$B$9))*Assumptions!$B$17)+((Assumptions!$B$30+Assumptions!$B$25)*Optimized!$B$6/1000*Assumptions!$B$16)+((Assumptions!$B$36+Assumptions!$B$38)*Optimized!$B$6)))<=0,"N/A",(((B$5*Optimized!$B$6)+(Assumptions!$B$41*((Assumptions!$B$7*$A12*1000000000)/(Assumptions!$B$9*3600)/1000000*Assumptions!$B$39))+Optimized!$B$26)-Assumptions!$B$45)/(Baseline!$B$13-((MAX(0,(Assumptions!$B$29*(Assumptions!$B$13/Assumptions!$B$12)*Optimized!$B$6/1000)-((((Assumptions!$B$7*$A12*1000000000)/(Assumptions!$B$9*3600)/1000000*Assumptions!$B$39)*Assumptions!$B$40)*Assumptions!$B$9))*Assumptions!$B$17)+((Assumptions!$B$30+Assumptions!$B$25)*Optimized!$B$6/1000*Assumptions!$B$16)+((Assumptions!$B$36+Assumptions!$B$38)*Optimized!$B$6)))) | C12: =IF((Baseline!$B$13-((MAX(0,(Assumptions!$B$29*(Assumptions!$B$13/Assumptions!$B$12)*Optimized!$B$6/1000)-((((Assumptions!$B$7*$A12*1000000000)/(Assumptions!$B$9*3600)/1000000*Assumptions!$B$39)*Assumptions!$B$40)*Assumptions!$B$9))*Assumptions!$B$17)+((Assumptions!$B$30+Assumptions!$B$25)*Optimized!$B$6/1000*Assumptions!$B$16)+((Assumptions!$B$36+Assumptions!$B$38)*Optimized!$B$6)))<=0,"N/A",(((C$5*Optimized!$B$6)+(Assumptions!$B$41*((Assumptions!$B$7*$A12*1000000000)/(Assumptions!$B$9*3600)/1000000*Assumptions!$B$39))+Optimized!$B$26)-Assumptions!$B$45)/(Baseline!$B$13-((MAX(0,(Assumptions!$B$29*(Assumptions!$B$13/Assumptions!$B$12)*Optimized!$B$6/1000)-((((Assumptions!$B$7*$A12*1000000000)/(Assumptions!$B$9*3600)/1000000*Assumptions!$B$39)*Assumptions!$B$40)*Assumptions!$B$9))*Assumptions!$B$17)+((Assumptions!$B$30+Assumptions!$B$25)*Optimized!$B$6/1000*Assumptions!$B$16)+((Assumptions!$B$36+Assumptions!$B$38)*Optimized!$B$6)))) | D12: =IF((Baseline!$B$13-((MAX(0,(Assumptions!$B$29*(Assumptions!$B$13/Assumptions!$B$12)*Optimized!$B$6/1000)-((((Assumptions!$B$7*$A12*1000000000)/(Assumptions!$B$9*3600)/1000000*Assumptions!$B$39)*Assumptions!$B$40)*Assumptions!$B$9))*Assumptions!$B$17)+((Assumptions!$B$30+Assumptions!$B$25)*Optimized!$B$6/1000*Assumptions!$B$16)+((Assumptions!$B$36+Assumptions!$B$38)*Optimized!$B$6)))<=0,"N/A",(((D$5*Optimized!$B$6)+(Assumptions!$B$41*((Assumptions!$B$7*$A12*1000000000)/(Assumptions!$B$9*3600)/1000000*Assumptions!$B$39))+Optimized!$B$26)-Assumptions!$B$45)/(Baseline!$B$13-((MAX(0,(Assumptions!$B$29*(Assumptions!$B$13/Assumptions!$B$12)*Optimized!$B$6/1000)-((((Assumptions!$B$7*$A12*1000000000)/(Assumptions!$B$9*3600)/1000000*Assumptions!$B$39)*Assumptions!$B$40)*Assumptions!$B$9))*Assumptions!$B$17)+((Assumptions!$B$30+Assumptions!$B$25)*Optimized!$B$6/1000*Assumptions!$B$16)+((Assumptions!$B$36+Assumptions!$B$38)*Optimized!$B$6)))) | E12: =IF((Baseline!$B$13-((MAX(0,(Assumptions!$B$29*(Assumptions!$B$13/Assumptions!$B$12)*Optimized!$B$6/1000)-((((Assumptions!$B$7*$A12*1000000000)/(Assumptions!$B$9*3600)/1000000*Assumptions!$B$39)*Assumptions!$B$40)*Assumptions!$B$9))*Assumptions!$B$17)+((Assumptions!$B$30+Assumptions!$B$25)*Optimized!$B$6/1000*Assumptions!$B$16)+((Assumptions!$B$36+Assumptions!$B$38)*Optimized!$B$6)))<=0,"N/A",(((E$5*Optimized!$B$6)+(Assumptions!$B$41*((Assumptions!$B$7*$A12*1000000000)/(Assumptions!$B$9*3600)/1000000*Assumptions!$B$39))+Optimized!$B$26)-Assumptions!$B$45)/(Baseline!$B$13-((MAX(0,(Assumptions!$B$29*(Assumptions!$B$13/Assumptions!$B$12)*Optimized!$B$6/1000)-((((Assumptions!$B$7*$A12*1000000000)/(Assumptions!$B$9*3600)/1000000*Assumptions!$B$39)*Assumptions!$B$40)*Assumptions!$B$9))*Assumptions!$B$17)+((Assumptions!$B$30+Assumptions!$B$25)*Optimized!$B$6/1000*Assumptions!$B$16)+((Assumptions!$B$36+Assumptions!$B$38)*Optimized!$B$6))))
A15: TABLE 2 — Savings £/t vs electricity tariff and baseline amine opex (unmitigated SOx cost)
A16: Tariff \ SOx degradation risk D (£/t) | B16: 2.04 | C16: 3.28 | D16: 6.25 | E16: 14 | F16: 15
A17: 85 | B17: =(((Assumptions!$B$29*(Assumptions!$B$13/Assumptions!$B$12))*Assumptions!$B$17/1000)+((Assumptions!$B$30+Assumptions!$B$25)*$A17/1000)+B$16+Baseline!$B$19)-(((Optimized!$B$12*Assumptions!$B$17)/Optimized!$B$6)+((Assumptions!$B$30+Assumptions!$B$25)*$A17/1000)+(Assumptions!$B$36+Assumptions!$B$38)+Optimized!$B$33) | C17: =(((Assumptions!$B$29*(Assumptions!$B$13/Assumptions!$B$12))*Assumptions!$B$17/1000)+((Assumptions!$B$30+Assumptions!$B$25)*$A17/1000)+C$16+Baseline!$B$19)-(((Optimized!$B$12*Assumptions!$B$17)/Optimized!$B$6)+((Assumptions!$B$30+Assumptions!$B$25)*$A17/1000)+(Assumptions!$B$36+Assumptions!$B$38)+Optimized!$B$33) | D17: =(((Assumptions!$B$29*(Assumptions!$B$13/Assumptions!$B$12))*Assumptions!$B$17/1000)+((Assumptions!$B$30+Assumptions!$B$25)*$A17/1000)+D$16+Baseline!$B$19)-(((Optimized!$B$12*Assumptions!$B$17)/Optimized!$B$6)+((Assumptions!$B$30+Assumptions!$B$25)*$A17/1000)+(Assumptions!$B$36+Assumptions!$B$38)+Optimized!$B$33) | E17: =(((Assumptions!$B$29*(Assumptions!$B$13/Assumptions!$B$12))*Assumptions!$B$17/1000)+((Assumptions!$B$30+Assumptions!$B$25)*$A17/1000)+E$16+Baseline!$B$19)-(((Optimized!$B$12*Assumptions!$B$17)/Optimized!$B$6)+((Assumptions!$B$30+Assumptions!$B$25)*$A17/1000)+(Assumptions!$B$36+Assumptions!$B$38)+Optimized!$B$33) | F17: =(((Assumptions!$B$29*(Assumptions!$B$13/Assumptions!$B$12))*Assumptions!$B$17/1000)+((Assumptions!$B$30+Assumptions!$B$25)*$A17/1000)+F$16+Baseline!$B$19)-(((Optimized!$B$12*Assumptions!$B$17)/Optimized!$B$6)+((Assumptions!$B$30+Assumptions!$B$25)*$A17/1000)+(Assumptions!$B$36+Assumptions!$B$38)+Optimized!$B$33)
A18: 95 | B18: =(((Assumptions!$B$29*(Assumptions!$B$13/Assumptions!$B$12))*Assumptions!$B$17/1000)+((Assumptions!$B$30+Assumptions!$B$25)*$A18/1000)+B$16+Baseline!$B$19)-(((Optimized!$B$12*Assumptions!$B$17)/Optimized!$B$6)+((Assumptions!$B$30+Assumptions!$B$25)*$A18/1000)+(Assumptions!$B$36+Assumptions!$B$38)+Optimized!$B$33) | C18: =(((Assumptions!$B$29*(Assumptions!$B$13/Assumptions!$B$12))*Assumptions!$B$17/1000)+((Assumptions!$B$30+Assumptions!$B$25)*$A18/1000)+C$16+Baseline!$B$19)-(((Optimized!$B$12*Assumptions!$B$17)/Optimized!$B$6)+((Assumptions!$B$30+Assumptions!$B$25)*$A18/1000)+(Assumptions!$B$36+Assumptions!$B$38)+Optimized!$B$33) | D18: =(((Assumptions!$B$29*(Assumptions!$B$13/Assumptions!$B$12))*Assumptions!$B$17/1000)+((Assumptions!$B$30+Assumptions!$B$25)*$A18/1000)+D$16+Baseline!$B$19)-(((Optimized!$B$12*Assumptions!$B$17)/Optimized!$B$6)+((Assumptions!$B$30+Assumptions!$B$25)*$A18/1000)+(Assumptions!$B$36+Assumptions!$B$38)+Optimized!$B$33) | E18: =(((Assumptions!$B$29*(Assumptions!$B$13/Assumptions!$B$12))*Assumptions!$B$17/1000)+((Assumptions!$B$30+Assumptions!$B$25)*$A18/1000)+E$16+Baseline!$B$19)-(((Optimized!$B$12*Assumptions!$B$17)/Optimized!$B$6)+((Assumptions!$B$30+Assumptions!$B$25)*$A18/1000)+(Assumptions!$B$36+Assumptions!$B$38)+Optimized!$B$33) | F18: =(((Assumptions!$B$29*(Assumptions!$B$13/Assumptions!$B$12))*Assumptions!$B$17/1000)+((Assumptions!$B$30+Assumptions!$B$25)*$A18/1000)+F$16+Baseline!$B$19)-(((Optimized!$B$12*Assumptions!$B$17)/Optimized!$B$6)+((Assumptions!$B$30+Assumptions!$B$25)*$A18/1000)+(Assumptions!$B$36+Assumptions!$B$38)+Optimized!$B$33)
A19: 105 | B19: =(((Assumptions!$B$29*(Assumptions!$B$13/Assumptions!$B$12))*Assumptions!$B$17/1000)+((Assumptions!$B$30+Assumptions!$B$25)*$A19/1000)+B$16+Baseline!$B$19)-(((Optimized!$B$12*Assumptions!$B$17)/Optimized!$B$6)+((Assumptions!$B$30+Assumptions!$B$25)*$A19/1000)+(Assumptions!$B$36+Assumptions!$B$38)+Optimized!$B$33) | C19: =(((Assumptions!$B$29*(Assumptions!$B$13/Assumptions!$B$12))*Assumptions!$B$17/1000)+((Assumptions!$B$30+Assumptions!$B$25)*$A19/1000)+C$16+Baseline!$B$19)-(((Optimized!$B$12*Assumptions!$B$17)/Optimized!$B$6)+((Assumptions!$B$30+Assumptions!$B$25)*$A19/1000)+(Assumptions!$B$36+Assumptions!$B$38)+Optimized!$B$33) | D19: =(((Assumptions!$B$29*(Assumptions!$B$13/Assumptions!$B$12))*Assumptions!$B$17/1000)+((Assumptions!$B$30+Assumptions!$B$25)*$A19/1000)+D$16+Baseline!$B$19)-(((Optimized!$B$12*Assumptions!$B$17)/Optimized!$B$6)+((Assumptions!$B$30+Assumptions!$B$25)*$A19/1000)+(Assumptions!$B$36+Assumptions!$B$38)+Optimized!$B$33) | E19: =(((Assumptions!$B$29*(Assumptions!$B$13/Assumptions!$B$12))*Assumptions!$B$17/1000)+((Assumptions!$B$30+Assumptions!$B$25)*$A19/1000)+E$16+Baseline!$B$19)-(((Optimized!$B$12*Assumptions!$B$17)/Optimized!$B$6)+((Assumptions!$B$30+Assumptions!$B$25)*$A19/1000)+(Assumptions!$B$36+Assumptions!$B$38)+Optimized!$B$33) | F19: =(((Assumptions!$B$29*(Assumptions!$B$13/Assumptions!$B$12))*Assumptions!$B$17/1000)+((Assumptions!$B$30+Assumptions!$B$25)*$A19/1000)+F$16+Baseline!$B$19)-(((Optimized!$B$12*Assumptions!$B$17)/Optimized!$B$6)+((Assumptions!$B$30+Assumptions!$B$25)*$A19/1000)+(Assumptions!$B$36+Assumptions!$B$38)+Optimized!$B$33)
A20: 115 | B20: =(((Assumptions!$B$29*(Assumptions!$B$13/Assumptions!$B$12))*Assumptions!$B$17/1000)+((Assumptions!$B$30+Assumptions!$B$25)*$A20/1000)+B$16+Baseline!$B$19)-(((Optimized!$B$12*Assumptions!$B$17)/Optimized!$B$6)+((Assumptions!$B$30+Assumptions!$B$25)*$A20/1000)+(Assumptions!$B$36+Assumptions!$B$38)+Optimized!$B$33) | C20: =(((Assumptions!$B$29*(Assumptions!$B$13/Assumptions!$B$12))*Assumptions!$B$17/1000)+((Assumptions!$B$30+Assumptions!$B$25)*$A20/1000)+C$16+Baseline!$B$19)-(((Optimized!$B$12*Assumptions!$B$17)/Optimized!$B$6)+((Assumptions!$B$30+Assumptions!$B$25)*$A20/1000)+(Assumptions!$B$36+Assumptions!$B$38)+Optimized!$B$33) | D20: =(((Assumptions!$B$29*(Assumptions!$B$13/Assumptions!$B$12))*Assumptions!$B$17/1000)+((Assumptions!$B$30+Assumptions!$B$25)*$A20/1000)+D$16+Baseline!$B$19)-(((Optimized!$B$12*Assumptions!$B$17)/Optimized!$B$6)+((Assumptions!$B$30+Assumptions!$B$25)*$A20/1000)+(Assumptions!$B$36+Assumptions!$B$38)+Optimized!$B$33) | E20: =(((Assumptions!$B$29*(Assumptions!$B$13/Assumptions!$B$12))*Assumptions!$B$17/1000)+((Assumptions!$B$30+Assumptions!$B$25)*$A20/1000)+E$16+Baseline!$B$19)-(((Optimized!$B$12*Assumptions!$B$17)/Optimized!$B$6)+((Assumptions!$B$30+Assumptions!$B$25)*$A20/1000)+(Assumptions!$B$36+Assumptions!$B$38)+Optimized!$B$33) | F20: =(((Assumptions!$B$29*(Assumptions!$B$13/Assumptions!$B$12))*Assumptions!$B$17/1000)+((Assumptions!$B$30+Assumptions!$B$25)*$A20/1000)+F$16+Baseline!$B$19)-(((Optimized!$B$12*Assumptions!$B$17)/Optimized!$B$6)+((Assumptions!$B$30+Assumptions!$B$25)*$A20/1000)+(Assumptions!$B$36+Assumptions!$B$38)+Optimized!$B$33)
A21: 125 | B21: =(((Assumptions!$B$29*(Assumptions!$B$13/Assumptions!$B$12))*Assumptions!$B$17/1000)+((Assumptions!$B$30+Assumptions!$B$25)*$A21/1000)+B$16+Baseline!$B$19)-(((Optimized!$B$12*Assumptions!$B$17)/Optimized!$B$6)+((Assumptions!$B$30+Assumptions!$B$25)*$A21/1000)+(Assumptions!$B$36+Assumptions!$B$38)+Optimized!$B$33) | C21: =(((Assumptions!$B$29*(Assumptions!$B$13/Assumptions!$B$12))*Assumptions!$B$17/1000)+((Assumptions!$B$30+Assumptions!$B$25)*$A21/1000)+C$16+Baseline!$B$19)-(((Optimized!$B$12*Assumptions!$B$17)/Optimized!$B$6)+((Assumptions!$B$30+Assumptions!$B$25)*$A21/1000)+(Assumptions!$B$36+Assumptions!$B$38)+Optimized!$B$33) | D21: =(((Assumptions!$B$29*(Assumptions!$B$13/Assumptions!$B$12))*Assumptions!$B$17/1000)+((Assumptions!$B$30+Assumptions!$B$25)*$A21/1000)+D$16+Baseline!$B$19)-(((Optimized!$B$12*Assumptions!$B$17)/Optimized!$B$6)+((Assumptions!$B$30+Assumptions!$B$25)*$A21/1000)+(Assumptions!$B$36+Assumptions!$B$38)+Optimized!$B$33) | E21: =(((Assumptions!$B$29*(Assumptions!$B$13/Assumptions!$B$12))*Assumptions!$B$17/1000)+((Assumptions!$B$30+Assumptions!$B$25)*$A21/1000)+E$16+Baseline!$B$19)-(((Optimized!$B$12*Assumptions!$B$17)/Optimized!$B$6)+((Assumptions!$B$30+Assumptions!$B$25)*$A21/1000)+(Assumptions!$B$36+Assumptions!$B$38)+Optimized!$B$33) | F21: =(((Assumptions!$B$29*(Assumptions!$B$13/Assumptions!$B$12))*Assumptions!$B$17/1000)+((Assumptions!$B$30+Assumptions!$B$25)*$A21/1000)+F$16+Baseline!$B$19)-(((Optimized!$B$12*Assumptions!$B$17)/Optimized!$B$6)+((Assumptions!$B$30+Assumptions!$B$25)*$A21/1000)+(Assumptions!$B$36+Assumptions!$B$38)+Optimized!$B$33)
A22: 140 | B22: =(((Assumptions!$B$29*(Assumptions!$B$13/Assumptions!$B$12))*Assumptions!$B$17/1000)+((Assumptions!$B$30+Assumptions!$B$25)*$A22/1000)+B$16+Baseline!$B$19)-(((Optimized!$B$12*Assumptions!$B$17)/Optimized!$B$6)+((Assumptions!$B$30+Assumptions!$B$25)*$A22/1000)+(Assumptions!$B$36+Assumptions!$B$38)+Optimized!$B$33) | C22: =(((Assumptions!$B$29*(Assumptions!$B$13/Assumptions!$B$12))*Assumptions!$B$17/1000)+((Assumptions!$B$30+Assumptions!$B$25)*$A22/1000)+C$16+Baseline!$B$19)-(((Optimized!$B$12*Assumptions!$B$17)/Optimized!$B$6)+((Assumptions!$B$30+Assumptions!$B$25)*$A22/1000)+(Assumptions!$B$36+Assumptions!$B$38)+Optimized!$B$33) | D22: =(((Assumptions!$B$29*(Assumptions!$B$13/Assumptions!$B$12))*Assumptions!$B$17/1000)+((Assumptions!$B$30+Assumptions!$B$25)*$A22/1000)+D$16+Baseline!$B$19)-(((Optimized!$B$12*Assumptions!$B$17)/Optimized!$B$6)+((Assumptions!$B$30+Assumptions!$B$25)*$A22/1000)+(Assumptions!$B$36+Assumptions!$B$38)+Optimized!$B$33) | E22: =(((Assumptions!$B$29*(Assumptions!$B$13/Assumptions!$B$12))*Assumptions!$B$17/1000)+((Assumptions!$B$30+Assumptions!$B$25)*$A22/1000)+E$16+Baseline!$B$19)-(((Optimized!$B$12*Assumptions!$B$17)/Optimized!$B$6)+((Assumptions!$B$30+Assumptions!$B$25)*$A22/1000)+(Assumptions!$B$36+Assumptions!$B$38)+Optimized!$B$33) | F22: =(((Assumptions!$B$29*(Assumptions!$B$13/Assumptions!$B$12))*Assumptions!$B$17/1000)+((Assumptions!$B$30+Assumptions!$B$25)*$A22/1000)+F$16+Baseline!$B$19)-(((Optimized!$B$12*Assumptions!$B$17)/Optimized!$B$6)+((Assumptions!$B$30+Assumptions!$B$25)*$A22/1000)+(Assumptions!$B$36+Assumptions!$B$38)+Optimized!$B$33)
A25: Table 1: B5=0 is the CENTRAL case (standard integrated DCC+caustic assumed sufficient, already inside the £399.6M baseline — payback driven only by specific heat/WHR uncertainty). C5/D5 model the DOWNSIDE scenario where a standalone SOx polisher turns out necessary (~10% probability per the Monte Carlo notebook) — a discrete risk, not a continuous central-case assumption. Table 2 isolates how much saving comes from the SOx degradation-risk assumption (D) alone vs the WHR thermal mechanism.
